<?xml version="1.0" ?>
<robot name="rotary_pendulum">

  <!-- Base -->
  <link name="base_link">
    <inertial>
      <mass value="0.2"/>
      <origin xyz="0 0 0" rpy="0 0 0"/>
      <inertia ixx="0.001" ixy="0" ixz="0"
               iyy="0.001" iyz="0"
               izz="0.001"/>
    </inertial>
    <visual>
      <origin xyz="0 0 0" rpy="0 0 0"/>
      <geometry>
        <box size="0.2 0.2 0.05"/>
      </geometry>
      <material name="gray">
        <color rgba="0.6 0.6 0.6 1"/>
      </material>
    </visual>
  </link>

  <!-- Arm -->
  <link name="arm_link">
    <inertial>
      <mass value="0.1"/>
      <origin xyz="0 0 0.25" rpy="0 0 0"/>
      <inertia ixx="0.0001" ixy="0" ixz="0"
               iyy="0.0001" iyz="0"
               izz="0.0001"/>
    </inertial>
    <visual>
      <origin xyz="0 0 0.25" rpy="0 0 0"/>
      <geometry>
        <box size="0.05 0.05 0.5"/>
      </geometry>
      <material name="blue">
        <color rgba="0.1 0.1 0.8 1"/>
      </material>
    </visual>
  </link>

  <!-- Revolute Joint: rotates around Y axis -->
  <joint name="base_to_arm" type="revolute">
    <parent link="base_link"/>
    <child link="arm_link"/>
    <origin xyz="0 0 0.025" rpy="0 0 0"/>
    <axis xyz="0 1 0"/>
    <limit effort="100.0" velocity="100.0" lower="-3.14" upper="3.14"/>
  </joint>

</robot>
